<robot name="onshape">
<link name="frame">
<visual>
<origin xyz="0 0 0" rpy="0 -0 0" />
<geometry>
<mesh filename="package:///frame.stl"/>
</geometry>
<material name="frame_material">
<color rgba="0.61568627450980395466 0.81176470588235294379 0.92941176470588238168 1.0"/>
</material>
</visual>
<collision>
<origin xyz="0 0 0" rpy="0 -0 0" />
<geometry>
<mesh filename="package:///frame.stl"/>
</geometry>
</collision>
<inertial>
<origin xyz="-1.9885447321080792328e-11 0.0013327326490887795706 -0.003833590599041345609" rpy="0 0 0"/>
<mass value="0.30997922518783177503" />
<inertia ixx="0.00054311890090477730596" ixy="-1.2862824116938768262e-13"  ixz="-1.6924260896451001613e-13" iyy="0.00047274655348398858436" iyz="6.6786579006804430226e-06" izz="0.00095080462472768817288" />
</inertial>
</link>

<link name="cwprop">
<visual>
<origin xyz="0 0 -0.0050000000000000001041" rpy="3.141592653589793116 -0 0" />
<geometry>
<mesh filename="package:///cwprop.stl"/>
</geometry>
<material name="cwprop_material">
<color rgba="0.61568627450980395466 0.81176470588235294379 0.92941176470588238168 1.0"/>
</material>
</visual>
<collision>
<origin xyz="0 0 -0.0050000000000000001041" rpy="3.141592653589793116 -0 0" />
<geometry>
<mesh filename="package:///cwprop.stl"/>
</geometry>
</collision>
<inertial>
<origin xyz="1.2208020479554607701e-11 -7.257042130721570693e-12 -0.005805260023183936996" rpy="0 0 0"/>
<mass value="0.0045608789483441887491" />
<inertia ixx="6.9169975866069136554e-07" ixy="-1.2324780152615035683e-16"  ixz="-2.1557298517195782329e-16" iyy="6.9169975836743447728e-07" iyz="1.4372788584271183588e-16" izz="1.3228943330621647579e-06" />
</inertial>
</link>

<joint name="cw_back" type="revolute">
<origin xyz="-0.05000000000000003747 0.049999999999999968081 -0.010000000000000000208" rpy="3.141592653589793116 -0 0" />
<parent link="frame" />
<child link="cwprop" />
<axis xyz="0 0 1"/>
<limit effort="1" velocity="20" />
<joint_properties friction="0.0"/>
</joint>

<link name="cwprop_2">
<visual>
<origin xyz="0 0 -0.0050000000000000001041" rpy="3.141592653589793116 -0 0" />
<geometry>
<mesh filename="package:///cwprop.stl"/>
</geometry>
<material name="cwprop_material">
<color rgba="0.61568627450980395466 0.81176470588235294379 0.92941176470588238168 1.0"/>
</material>
</visual>
<collision>
<origin xyz="0 0 -0.0050000000000000001041" rpy="3.141592653589793116 -0 0" />
<geometry>
<mesh filename="package:///cwprop.stl"/>
</geometry>
</collision>
<inertial>
<origin xyz="1.2208020479554607701e-11 -7.257042130721570693e-12 -0.005805260023183936996" rpy="0 0 0"/>
<mass value="0.0045608789483441887491" />
<inertia ixx="6.9169975866069136554e-07" ixy="-1.2324780152615035683e-16"  ixz="-2.1557298517195782329e-16" iyy="6.9169975836743447728e-07" iyz="1.4372788584271183588e-16" izz="1.3228943330621647579e-06" />
</inertial>
</link>

<joint name="cw_front" type="revolute">
<origin xyz="0.050000000000000016653 -0.049999999999999988898 -0.010000000000000000208" rpy="3.141592653589793116 -0 0" />
<parent link="frame" />
<child link="cwprop_2" />
<axis xyz="0 0 1"/>
<limit effort="1" velocity="20" />
<joint_properties friction="0.0"/>
</joint>

<link name="ccwprop">
<visual>
<origin xyz="0 0 -0.0050000000000000001041" rpy="3.141592653589793116 -0 0" />
<geometry>
<mesh filename="package:///ccwprop.stl"/>
</geometry>
<material name="ccwprop_material">
<color rgba="0.61568627450980395466 0.81176470588235294379 0.92941176470588238168 1.0"/>
</material>
</visual>
<collision>
<origin xyz="0 0 -0.0050000000000000001041" rpy="3.141592653589793116 -0 0" />
<geometry>
<mesh filename="package:///ccwprop.stl"/>
</geometry>
</collision>
<inertial>
<origin xyz="-5.3871031168963844069e-10 1.090148365011414741e-09 -0.0058054487327012741643" rpy="0 0 0"/>
<mass value="0.0045605471506329564937" />
<inertia ixx="6.9167056821239557089e-07" ixy="9.7821298862343853667e-15"  ixz="9.4821324427574322039e-15" iyy="6.9167054890854604318e-07" iyz="-1.9438534456370197683e-14" izz="1.3228368598726339292e-06" />
</inertial>
</link>

<joint name="ccw_back" type="revolute">
<origin xyz="0.050000000000000016653 0.050000000000000030531 -0.010000000000000000208" rpy="3.141592653589793116 -0 0" />
<parent link="frame" />
<child link="ccwprop" />
<axis xyz="0 0 1"/>
<limit effort="1" velocity="20" />
<joint_properties friction="0.0"/>
</joint>

<link name="ccwprop_2">
<visual>
<origin xyz="0 0 -0.0050000000000000001041" rpy="3.141592653589793116 -0 0" />
<geometry>
<mesh filename="package:///ccwprop.stl"/>
</geometry>
<material name="ccwprop_material">
<color rgba="0.61568627450980395466 0.81176470588235294379 0.92941176470588238168 1.0"/>
</material>
</visual>
<collision>
<origin xyz="0 0 -0.0050000000000000001041" rpy="3.141592653589793116 -0 0" />
<geometry>
<mesh filename="package:///ccwprop.stl"/>
</geometry>
</collision>
<inertial>
<origin xyz="-5.3871031168963844069e-10 1.090148365011414741e-09 -0.0058054487327012741643" rpy="0 0 0"/>
<mass value="0.0045605471506329564937" />
<inertia ixx="6.9167056821239557089e-07" ixy="9.7821298862343853667e-15"  ixz="9.4821324427574322039e-15" iyy="6.9167054890854604318e-07" iyz="-1.9438534456370197683e-14" izz="1.3228368598726339292e-06" />
</inertial>
</link>

<joint name="ccw_front" type="revolute">
<origin xyz="-0.049999999999999981959 -0.050000000000000016653 -0.010000000000000000208" rpy="3.141592653589793116 -0 0" />
<parent link="frame" />
<child link="ccwprop_2" />
<axis xyz="0 0 1"/>
<limit effort="1" velocity="20" />
<joint_properties friction="0.0"/>
</joint>


</robot>
